2020-01-09 23:26:21,927 ERROR: Exception on /favicon.ico [GET] [in /Users/lukazphelps/.pyenv/versions/3.8.1/lib/python3.8/site-packages/flask/app.py:1890]
Traceback (most recent call last):
  File "/Users/lukazphelps/.pyenv/versions/3.8.1/lib/python3.8/site-packages/flask/app.py", line 1949, in full_dispatch_request
    rv = self.dispatch_request()
  File "/Users/lukazphelps/.pyenv/versions/3.8.1/lib/python3.8/site-packages/flask/app.py", line 1925, in dispatch_request
    self.raise_routing_exception(req)
  File "/Users/lukazphelps/.pyenv/versions/3.8.1/lib/python3.8/site-packages/flask/app.py", line 1907, in raise_routing_exception
    raise request.routing_exception
  File "/Users/lukazphelps/.pyenv/versions/3.8.1/lib/python3.8/site-packages/flask/ctx.py", line 350, in match_request
    result = self.url_adapter.match(return_rule=True)
  File "/Users/lukazphelps/.pyenv/versions/3.8.1/lib/python3.8/site-packages/werkzeug/routing.py", line 1799, in match
    raise NotFound()
werkzeug.exceptions.NotFound: 404 Not Found: The requested URL was not found on the server. If you entered the URL manually please check your spelling and try again.

During handling of the above exception, another exception occurred:

Traceback (most recent call last):
  File "/Users/lukazphelps/.pyenv/versions/3.8.1/lib/python3.8/site-packages/flask/app.py", line 2446, in wsgi_app
    response = self.full_dispatch_request()
  File "/Users/lukazphelps/.pyenv/versions/3.8.1/lib/python3.8/site-packages/flask/app.py", line 1951, in full_dispatch_request
    rv = self.handle_user_exception(e)
  File "/Users/lukazphelps/.pyenv/versions/3.8.1/lib/python3.8/site-packages/flask/app.py", line 1815, in handle_user_exception
    return self.handle_http_exception(e)
  File "/Users/lukazphelps/.pyenv/versions/3.8.1/lib/python3.8/site-packages/flask/app.py", line 1743, in handle_http_exception
    return handler(e)
  File "/Users/lukazphelps/Desktop/SchoolCode/Mythril_Sheets/app/errors.py", line 7, in not_found_error
    return render_template('404.html'), 404
  File "/Users/lukazphelps/.pyenv/versions/3.8.1/lib/python3.8/site-packages/flask/templating.py", line 137, in render_template
    return _render(
  File "/Users/lukazphelps/.pyenv/versions/3.8.1/lib/python3.8/site-packages/flask/templating.py", line 120, in _render
    rv = template.render(context)
  File "/Users/lukazphelps/.pyenv/versions/3.8.1/lib/python3.8/site-packages/jinja2/asyncsupport.py", line 76, in render
    return original_render(self, *args, **kwargs)
  File "/Users/lukazphelps/.pyenv/versions/3.8.1/lib/python3.8/site-packages/jinja2/environment.py", line 1008, in render
    return self.environment.handle_exception(exc_info, True)
  File "/Users/lukazphelps/.pyenv/versions/3.8.1/lib/python3.8/site-packages/jinja2/environment.py", line 780, in handle_exception
    reraise(exc_type, exc_value, tb)
  File "/Users/lukazphelps/.pyenv/versions/3.8.1/lib/python3.8/site-packages/jinja2/_compat.py", line 37, in reraise
    raise value.with_traceback(tb)
  File "/Users/lukazphelps/Desktop/SchoolCode/Mythril_Sheets/app/templates/404.html", line 1, in <module>
    {% extends "base.html" %}
  File "/Users/lukazphelps/.pyenv/versions/3.8.1/lib/python3.8/site-packages/jinja2/environment.py", line 1005, in render
    return concat(self.root_render_func(self.new_context(vars)))
  File "/Users/lukazphelps/Desktop/SchoolCode/Mythril_Sheets/app/templates/404.html", line 14, in root
  File "/Users/lukazphelps/Desktop/SchoolCode/Mythril_Sheets/app/templates/base.html", line 12, in root
    <script src="https://code.jquery.com/jquery-3.4.1.slim.min.js"
  File "/Users/lukazphelps/Desktop/SchoolCode/Mythril_Sheets/app/templates/partials/nav.html", line 29, in root
  File "/Users/lukazphelps/.pyenv/versions/3.8.1/lib/python3.8/site-packages/jinja2/environment.py", line 430, in getattr
    return getattr(obj, attribute)
jinja2.exceptions.UndefinedError: 'user' is undefined
2020-01-09 23:26:45,349 ERROR: Exception on /pages [GET] [in /Users/lukazphelps/.pyenv/versions/3.8.1/lib/python3.8/site-packages/flask/app.py:1890]
Traceback (most recent call last):
  File "/Users/lukazphelps/.pyenv/versions/3.8.1/lib/python3.8/site-packages/flask/app.py", line 2446, in wsgi_app
    response = self.full_dispatch_request()
  File "/Users/lukazphelps/.pyenv/versions/3.8.1/lib/python3.8/site-packages/flask/app.py", line 1951, in full_dispatch_request
    rv = self.handle_user_exception(e)
  File "/Users/lukazphelps/.pyenv/versions/3.8.1/lib/python3.8/site-packages/flask/app.py", line 1820, in handle_user_exception
    reraise(exc_type, exc_value, tb)
  File "/Users/lukazphelps/.pyenv/versions/3.8.1/lib/python3.8/site-packages/flask/_compat.py", line 39, in reraise
    raise value
  File "/Users/lukazphelps/.pyenv/versions/3.8.1/lib/python3.8/site-packages/flask/app.py", line 1949, in full_dispatch_request
    rv = self.dispatch_request()
  File "/Users/lukazphelps/.pyenv/versions/3.8.1/lib/python3.8/site-packages/flask/app.py", line 1935, in dispatch_request
    return self.view_functions[rule.endpoint](**req.view_args)
  File "/Users/lukazphelps/.pyenv/versions/3.8.1/lib/python3.8/site-packages/flask_login/utils.py", line 261, in decorated_view
    return func(*args, **kwargs)
  File "/Users/lukazphelps/Desktop/SchoolCode/Mythril_Sheets/app/routes.py", line 134, in pages
    return render_template("sheets.html", title='Sheets', sheets=sheets, form=form)
  File "/Users/lukazphelps/.pyenv/versions/3.8.1/lib/python3.8/site-packages/flask/templating.py", line 137, in render_template
    return _render(
  File "/Users/lukazphelps/.pyenv/versions/3.8.1/lib/python3.8/site-packages/flask/templating.py", line 120, in _render
    rv = template.render(context)
  File "/Users/lukazphelps/.pyenv/versions/3.8.1/lib/python3.8/site-packages/jinja2/asyncsupport.py", line 76, in render
    return original_render(self, *args, **kwargs)
  File "/Users/lukazphelps/.pyenv/versions/3.8.1/lib/python3.8/site-packages/jinja2/environment.py", line 1008, in render
    return self.environment.handle_exception(exc_info, True)
  File "/Users/lukazphelps/.pyenv/versions/3.8.1/lib/python3.8/site-packages/jinja2/environment.py", line 780, in handle_exception
    reraise(exc_type, exc_value, tb)
  File "/Users/lukazphelps/.pyenv/versions/3.8.1/lib/python3.8/site-packages/jinja2/_compat.py", line 37, in reraise
    raise value.with_traceback(tb)
  File "/Users/lukazphelps/Desktop/SchoolCode/Mythril_Sheets/app/templates/sheets.html", line 2, in <module>
    {% import 'bootstrap/wtf.html' as wtf %}
  File "/Users/lukazphelps/.pyenv/versions/3.8.1/lib/python3.8/site-packages/jinja2/environment.py", line 1005, in render
    return concat(self.root_render_func(self.new_context(vars)))
  File "/Users/lukazphelps/Desktop/SchoolCode/Mythril_Sheets/app/templates/sheets.html", line 17, in root
    {% endif %}
  File "/Users/lukazphelps/Desktop/SchoolCode/Mythril_Sheets/app/templates/base.html", line 12, in root
    <script src="https://code.jquery.com/jquery-3.4.1.slim.min.js"
  File "/Users/lukazphelps/Desktop/SchoolCode/Mythril_Sheets/app/templates/partials/nav.html", line 29, in root
  File "/Users/lukazphelps/.pyenv/versions/3.8.1/lib/python3.8/site-packages/jinja2/environment.py", line 430, in getattr
    return getattr(obj, attribute)
jinja2.exceptions.UndefinedError: 'user' is undefined
